ERROR 2025-10-14T16:15:05.283318Z Traceback (most recent call last): File "<frozen runpy>", line 198, in _run_module_as_main File "<frozen runpy>", line 88, in _run_code File "/usr/local/lib/python3.11/site-packages/uvicorn/__main__.py", line 4, in <module> uvicorn.main() File "/usr/local/lib/python3.11/site-packages/click/core.py", line 1442, in __call__ return self.main(*args, **kwargs) ^^^^^^^^^^^^^^^^^^^^^^^^^^ File "/usr/local/lib/python3.11/site-packages/click/core.py", line 1363, in main rv = self.invoke(ctx) ^^^^^^^^^^^^^^^^ File "/usr/local/lib/python3.11/site-packages/click/core.py", line 1226, in invoke return ctx.invoke(self.callback, **ctx.params) ^^^^^^^^^^^^^^^^^^^^^^^^^^^^^^^^^^^^^^^ File "/usr/local/lib/python3.11/site-packages/click/core.py", line 794, in invoke return callback(*args, **kwargs) ^^^^^^^^^^^^^^^^^^^^^^^^^ File "/usr/local/lib/python3.11/site-packages/uvicorn/main.py", line 413, in main run( File "/usr/local/lib/python3.11/site-packages/uvicorn/main.py", line 580, in run server.run() File "/usr/local/lib/python3.11/site-packages/uvicorn/server.py", line 67, in run return asyncio.run(self.serve(sockets=sockets)) ^^^^^^^^^^^^^^^^^^^^^^^^^^^^^^^^^^^^^^^^ File "/usr/local/lib/python3.11/asyncio/runners.py", line 190, in run return runner.run(main) ^^^^^^^^^^^^^^^^ File "/usr/local/lib/python3.11/asyncio/runners.py", line 118, in run return self._loop.run_until_complete(task) ^^^^^^^^^^^^^^^^^^^^^^^^^^^^^^^^^^^ File "/usr/local/lib/python3.11/asyncio/base_events.py", line 654, in run_until_complete return future.result() ^^^^^^^^^^^^^^^ File "/usr/local/lib/python3.11/site-packages/uvicorn/server.py", line 71, in serve await self._serve(sockets) File "/usr/local/lib/python3.11/site-packages/uvicorn/server.py", line 78, in _serve config.load() File "/usr/local/lib/python3.11/site-packages/uvicorn/config.py", line 436, in load self.loaded_app = import_from_string(self.app) ^^^^^^^^^^^^^^^^^^^^^^^^^^^^ File "/usr/local/lib/python3.11/site-packages/uvicorn/importer.py", line 19, in import_from_string module = importlib.import_module(module_str) ^^^^^^^^^^^^^^^^^^^^^^^^^^^^^^^^^^^ File "/usr/local/lib/python3.11/importlib/__init__.py", line 126, in import_module return _bootstrap._gcd_import(name[level:], package, level) ^^^^^^^^^^^^^^^^^^^â€¦
  {
    "textPayload": "Traceback (most recent call last):\n  File \"<frozen runpy>\", line 198, in _run_module_as_main\n  File \"<frozen runpy>\", line 88, in _run_code\n  File \"/usr/local/lib/python3.11/site-packages/uvicorn/__main__.py\", line 4, in <module>\n    uvicorn.main()\n  File \"/usr/local/lib/python3.11/site-packages/click/core.py\", line 1442, in __call__\n    return self.main(*args, **kwargs)\n           ^^^^^^^^^^^^^^^^^^^^^^^^^^\n  File \"/usr/local/lib/python3.11/site-packages/click/core.py\", line 1363, in main\n    rv = self.invoke(ctx)\n         ^^^^^^^^^^^^^^^^\n  File \"/usr/local/lib/python3.11/site-packages/click/core.py\", line 1226, in invoke\n    return ctx.invoke(self.callback, **ctx.params)\n           ^^^^^^^^^^^^^^^^^^^^^^^^^^^^^^^^^^^^^^^\n  File \"/usr/local/lib/python3.11/site-packages/click/core.py\", line 794, in invoke\n    return callback(*args, **kwargs)\n           ^^^^^^^^^^^^^^^^^^^^^^^^^\n  File \"/usr/local/lib/python3.11/site-packages/uvicorn/main.py\", line 413, in main\n    run(\n  File \"/usr/local/lib/python3.11/site-packages/uvicorn/main.py\", line 580, in run\n    server.run()\n  File \"/usr/local/lib/python3.11/site-packages/uvicorn/server.py\", line 67, in run\n    return asyncio.run(self.serve(sockets=sockets))\n           ^^^^^^^^^^^^^^^^^^^^^^^^^^^^^^^^^^^^^^^^\n  File \"/usr/local/lib/python3.11/asyncio/runners.py\", line 190, in run\n    return runner.run(main)\n           ^^^^^^^^^^^^^^^^\n  File \"/usr/local/lib/python3.11/asyncio/runners.py\", line 118, in run\n    return self._loop.run_until_complete(task)\n           ^^^^^^^^^^^^^^^^^^^^^^^^^^^^^^^^^^^\n  File \"/usr/local/lib/python3.11/asyncio/base_events.py\", line 654, in run_until_complete\n    return future.result()\n           ^^^^^^^^^^^^^^^\n  File \"/usr/local/lib/python3.11/site-packages/uvicorn/server.py\", line 71, in serve\n    await self._serve(sockets)\n  File \"/usr/local/lib/python3.11/site-packages/uvicorn/server.py\", line 78, in _serve\n    config.load()\n  File \"/usr/local/lib/python3.11/site-packages/uvicorn/config.py\", line 436, in load\n    self.loaded_app = import_from_string(self.app)\n                      ^^^^^^^^^^^^^^^^^^^^^^^^^^^^\n  File \"/usr/local/lib/python3.11/site-packages/uvicorn/importer.py\", line 19, in import_from_string\n    module = importlib.import_module(module_str)\n             ^^^^^^^^^^^^^^^^^^^^^^^^^^^^^^^^^^^\n  File \"/usr/local/lib/python3.11/importlib/__init__.py\", line 126, in import_module\n    return _bootstrap._gcd_import(name[level:], package, level)\n           ^^^^^^^^^^^^^^^^^^^^^^^^^^^^^^^^^^^^^^^^^^^^^^^^^^^^\n  File \"<frozen importlib._bootstrap>\", line 1204, in _gcd_import\n  File \"<frozen importlib._bootstrap>\", line 1176, in _find_and_load\n  File \"<frozen importlib._bootstrap>\", line 1147, in _find_and_load_unlocked\n  File \"<frozen importlib._bootstrap>\", line 690, in _load_unlocked\n  File \"<frozen importlib._bootstrap_external>\", line 940, in exec_module\n  File \"<frozen importlib._bootstrap>\", line 241, in _call_with_frames_removed\n  File \"/app/api/main.py\", line 27, in <module>\n    from .auth import (get_password_hash, verify_password, create_access_token,\n  File \"/app/api/auth.py\", line 19, in <module>\n    raise ValueError(\"SECURITY ERROR: JWT_SECRET environment variable is required. Set it to a cryptographically secure random value.\")\nValueError: SECURITY ERROR: JWT_SECRET environment variable is required. Set it to a cryptographically secure random value.",
    "insertId": "68ee7709000452b647c0bbd5",
    "resource": {
      "type": "cloud_run_revision",
      "labels": {
        "service_name": "fastapi",
        "configuration_name": "fastapi",
        "project_id": "gen-lang-client-0816724031",
        "revision_name": "fastapi-00004-zlw",
        "location": "europe-west1"
      }
    },
    "timestamp": "2025-10-14T16:15:05.283318Z",
    "severity": "ERROR",
    "labels": {
      "commit-sha": "b68e82fc4d56a1f0eaeab871f8b6401b340572fc",
      "instanceId": "0069c7a988f553f2583e7ab653f9477f1f1252c694c651d6d9ac0765275538e2bd0c98f24809773cc2b0ad05d35f59c21c5bc001b8f7dfcad02020b75f0387ad1004987bfe21e6c3e6047c54f112bb",
      "gcb-trigger-id": "9f8a3215-26e3-4245-a725-6fe37cb04c2c",
      "gcb-build-id": "73274d8f-7c59-4712-a113-97a45b66bd53",
      "managed-by": "gcp-cloud-build-deploy-cloud-run",
      "gcb-trigger-region": "global"
    },
    "logName": "projects/gen-lang-client-0816724031/logs/run.googleapis.com%2Fstderr",
    "receiveTimestamp": "2025-10-14T16:15:05.287912465Z",
    "errorGroups": [
      {
        "id": "CJ7wkbCZ19SvjgE"
      }
    ]
  }
